[2023-02-16T10:55:19.179+0000] {taskinstance.py:1087} INFO - Dependencies all met for <TaskInstance: abcd.EXTRACTING_DATA manual__2023-02-16T10:55:10.787521+00:00 [queued]>
[2023-02-16T10:55:19.198+0000] {taskinstance.py:1087} INFO - Dependencies all met for <TaskInstance: abcd.EXTRACTING_DATA manual__2023-02-16T10:55:10.787521+00:00 [queued]>
[2023-02-16T10:55:19.199+0000] {taskinstance.py:1283} INFO - 
--------------------------------------------------------------------------------
[2023-02-16T10:55:19.200+0000] {taskinstance.py:1284} INFO - Starting attempt 1 of 2
[2023-02-16T10:55:19.202+0000] {taskinstance.py:1285} INFO - 
--------------------------------------------------------------------------------
[2023-02-16T10:55:19.228+0000] {taskinstance.py:1304} INFO - Executing <Task(PythonOperator): EXTRACTING_DATA> on 2023-02-16 10:55:10.787521+00:00
[2023-02-16T10:55:19.237+0000] {standard_task_runner.py:55} INFO - Started process 178 to run task
[2023-02-16T10:55:19.243+0000] {standard_task_runner.py:82} INFO - Running: ['***', 'tasks', 'run', 'abcd', 'EXTRACTING_DATA', 'manual__2023-02-16T10:55:10.787521+00:00', '--job-id', '110', '--raw', '--subdir', 'DAGS_FOLDER/dag_scrape_specific.py', '--cfg-path', '/tmp/tmpq7g9aaq4']
[2023-02-16T10:55:19.245+0000] {standard_task_runner.py:83} INFO - Job 110: Subtask EXTRACTING_DATA
[2023-02-16T10:55:19.369+0000] {task_command.py:389} INFO - Running <TaskInstance: abcd.EXTRACTING_DATA manual__2023-02-16T10:55:10.787521+00:00 [running]> on host 55b685598511
[2023-02-16T10:55:19.497+0000] {taskinstance.py:1513} INFO - Exporting the following env vars:
AIRFLOW_CTX_DAG_EMAIL=test@test.com
AIRFLOW_CTX_DAG_OWNER=test
AIRFLOW_CTX_DAG_ID=abcd
AIRFLOW_CTX_TASK_ID=EXTRACTING_DATA
AIRFLOW_CTX_EXECUTION_DATE=2023-02-16T10:55:10.787521+00:00
AIRFLOW_CTX_TRY_NUMBER=1
AIRFLOW_CTX_DAG_RUN_ID=manual__2023-02-16T10:55:10.787521+00:00
[2023-02-16T10:55:20.448+0000] {taskinstance.py:1772} ERROR - Task failed with exception
Traceback (most recent call last):
  File "/home/airflow/.local/lib/python3.7/site-packages/airflow/operators/python.py", line 175, in execute
    return_value = self.execute_callable()
  File "/home/airflow/.local/lib/python3.7/site-packages/airflow/operators/python.py", line 192, in execute_callable
    return self.python_callable(*self.op_args, **self.op_kwargs)
  File "/opt/airflow/dags/dag_scrape_specific.py", line 53, in extract_data_send_to_snowflake
    df_test.to_sql('match_results', con=engine, index=False)
NameError: name 'engine' is not defined
[2023-02-16T10:55:20.464+0000] {taskinstance.py:1327} INFO - Marking task as UP_FOR_RETRY. dag_id=abcd, task_id=EXTRACTING_DATA, execution_date=20230216T105510, start_date=20230216T105519, end_date=20230216T105520
[2023-02-16T10:55:20.496+0000] {warnings.py:110} WARNING - /home/***/.local/lib/python3.7/site-packages/***/utils/email.py:120: RemovedInAirflow3Warning: Fetching SMTP credentials from configuration variables will be deprecated in a future release. Please set credentials using a connection instead.
  send_mime_email(e_from=mail_from, e_to=recipients, mime_msg=msg, conn_id=conn_id, dryrun=dryrun)

[2023-02-16T10:55:20.498+0000] {configuration.py:635} WARNING - section/key [smtp/smtp_user] not found in config
[2023-02-16T10:55:20.499+0000] {email.py:229} INFO - Email alerting: attempt 1
[2023-02-16T10:55:20.511+0000] {configuration.py:635} WARNING - section/key [smtp/smtp_user] not found in config
[2023-02-16T10:55:20.512+0000] {email.py:229} INFO - Email alerting: attempt 1
[2023-02-16T10:55:20.514+0000] {taskinstance.py:1835} ERROR - Failed to send email to: test@test.com
Traceback (most recent call last):
  File "/home/airflow/.local/lib/python3.7/site-packages/airflow/models/taskinstance.py", line 1378, in _run_raw_task
    self._execute_task_with_callbacks(context, test_mode)
  File "/home/airflow/.local/lib/python3.7/site-packages/airflow/models/taskinstance.py", line 1524, in _execute_task_with_callbacks
    result = self._execute_task(context, task_orig)
  File "/home/airflow/.local/lib/python3.7/site-packages/airflow/models/taskinstance.py", line 1585, in _execute_task
    result = execute_callable(context=context)
  File "/home/airflow/.local/lib/python3.7/site-packages/airflow/operators/python.py", line 175, in execute
    return_value = self.execute_callable()
  File "/home/airflow/.local/lib/python3.7/site-packages/airflow/operators/python.py", line 192, in execute_callable
    return self.python_callable(*self.op_args, **self.op_kwargs)
  File "/opt/airflow/dags/dag_scrape_specific.py", line 53, in extract_data_send_to_snowflake
    df_test.to_sql('match_results', con=engine, index=False)
NameError: name 'engine' is not defined

During handling of the above exception, another exception occurred:

Traceback (most recent call last):
  File "/home/airflow/.local/lib/python3.7/site-packages/airflow/models/taskinstance.py", line 2235, in email_alert
    send_email(task.email, subject, html_content)
  File "/home/airflow/.local/lib/python3.7/site-packages/airflow/utils/email.py", line 72, in send_email
    **kwargs,
  File "/home/airflow/.local/lib/python3.7/site-packages/airflow/utils/email.py", line 120, in send_email_smtp
    send_mime_email(e_from=mail_from, e_to=recipients, mime_msg=msg, conn_id=conn_id, dryrun=dryrun)
  File "/home/airflow/.local/lib/python3.7/site-packages/airflow/utils/email.py", line 231, in send_mime_email
    smtp_conn = _get_smtp_connection(smtp_host, smtp_port, smtp_timeout, smtp_ssl)
  File "/home/airflow/.local/lib/python3.7/site-packages/airflow/utils/email.py", line 265, in _get_smtp_connection
    else smtplib.SMTP(host=host, port=port, timeout=timeout)
  File "/usr/local/lib/python3.7/smtplib.py", line 251, in __init__
    (code, msg) = self.connect(host, port)
  File "/usr/local/lib/python3.7/smtplib.py", line 336, in connect
    self.sock = self._get_socket(host, port, self.timeout)
  File "/usr/local/lib/python3.7/smtplib.py", line 307, in _get_socket
    self.source_address)
  File "/usr/local/lib/python3.7/socket.py", line 728, in create_connection
    raise err
  File "/usr/local/lib/python3.7/socket.py", line 716, in create_connection
    sock.connect(sa)
OSError: [Errno 99] Cannot assign requested address

During handling of the above exception, another exception occurred:

Traceback (most recent call last):
  File "/home/airflow/.local/lib/python3.7/site-packages/airflow/models/taskinstance.py", line 1833, in handle_failure
    self.email_alert(error, task)
  File "/home/airflow/.local/lib/python3.7/site-packages/airflow/models/taskinstance.py", line 2237, in email_alert
    send_email(task.email, subject, html_content_err)
  File "/home/airflow/.local/lib/python3.7/site-packages/airflow/utils/email.py", line 72, in send_email
    **kwargs,
  File "/home/airflow/.local/lib/python3.7/site-packages/airflow/utils/email.py", line 120, in send_email_smtp
    send_mime_email(e_from=mail_from, e_to=recipients, mime_msg=msg, conn_id=conn_id, dryrun=dryrun)
  File "/home/airflow/.local/lib/python3.7/site-packages/airflow/utils/email.py", line 231, in send_mime_email
    smtp_conn = _get_smtp_connection(smtp_host, smtp_port, smtp_timeout, smtp_ssl)
  File "/home/airflow/.local/lib/python3.7/site-packages/airflow/utils/email.py", line 265, in _get_smtp_connection
    else smtplib.SMTP(host=host, port=port, timeout=timeout)
  File "/usr/local/lib/python3.7/smtplib.py", line 251, in __init__
    (code, msg) = self.connect(host, port)
  File "/usr/local/lib/python3.7/smtplib.py", line 336, in connect
    self.sock = self._get_socket(host, port, self.timeout)
  File "/usr/local/lib/python3.7/smtplib.py", line 307, in _get_socket
    self.source_address)
  File "/usr/local/lib/python3.7/socket.py", line 728, in create_connection
    raise err
  File "/usr/local/lib/python3.7/socket.py", line 716, in create_connection
    sock.connect(sa)
OSError: [Errno 99] Cannot assign requested address
[2023-02-16T10:55:20.543+0000] {standard_task_runner.py:105} ERROR - Failed to execute job 110 for task EXTRACTING_DATA (name 'engine' is not defined; 178)
[2023-02-16T10:55:20.583+0000] {local_task_job.py:159} INFO - Task exited with return code 1
[2023-02-16T10:55:20.625+0000] {taskinstance.py:2582} INFO - 0 downstream tasks scheduled from follow-on schedule check
