[2023-02-17T08:22:57.540+0000] {taskinstance.py:1087} INFO - Dependencies all met for <TaskInstance: dag_scrape_managers.EXTRACTING_DATA manual__2023-02-17T08:22:52.323879+00:00 [queued]>
[2023-02-17T08:22:57.767+0000] {taskinstance.py:1087} INFO - Dependencies all met for <TaskInstance: dag_scrape_managers.EXTRACTING_DATA manual__2023-02-17T08:22:52.323879+00:00 [queued]>
[2023-02-17T08:22:57.769+0000] {taskinstance.py:1283} INFO - 
--------------------------------------------------------------------------------
[2023-02-17T08:22:57.771+0000] {taskinstance.py:1284} INFO - Starting attempt 1 of 2
[2023-02-17T08:22:57.773+0000] {taskinstance.py:1285} INFO - 
--------------------------------------------------------------------------------
[2023-02-17T08:22:57.795+0000] {taskinstance.py:1304} INFO - Executing <Task(PythonOperator): EXTRACTING_DATA> on 2023-02-17 08:22:52.323879+00:00
[2023-02-17T08:22:57.807+0000] {standard_task_runner.py:55} INFO - Started process 294 to run task
[2023-02-17T08:22:57.813+0000] {standard_task_runner.py:82} INFO - Running: ['***', 'tasks', 'run', 'dag_scrape_managers', 'EXTRACTING_DATA', 'manual__2023-02-17T08:22:52.323879+00:00', '--job-id', '137', '--raw', '--subdir', 'DAGS_FOLDER/dag_scrape_managers.py', '--cfg-path', '/tmp/tmp55tqinim']
[2023-02-17T08:22:57.819+0000] {standard_task_runner.py:83} INFO - Job 137: Subtask EXTRACTING_DATA
[2023-02-17T08:22:57.950+0000] {task_command.py:389} INFO - Running <TaskInstance: dag_scrape_managers.EXTRACTING_DATA manual__2023-02-17T08:22:52.323879+00:00 [running]> on host 55b685598511
[2023-02-17T08:22:58.118+0000] {taskinstance.py:1513} INFO - Exporting the following env vars:
AIRFLOW_CTX_DAG_EMAIL=test@test.com
AIRFLOW_CTX_DAG_OWNER=test
AIRFLOW_CTX_DAG_ID=dag_scrape_managers
AIRFLOW_CTX_TASK_ID=EXTRACTING_DATA
AIRFLOW_CTX_EXECUTION_DATE=2023-02-17T08:22:52.323879+00:00
AIRFLOW_CTX_TRY_NUMBER=1
AIRFLOW_CTX_DAG_RUN_ID=manual__2023-02-17T08:22:52.323879+00:00
[2023-02-17T08:22:58.582+0000] {connection.py:285} INFO - Snowflake Connector for Python Version: 3.0.0, Python Version: 3.7.15, Platform: Linux-5.15.49-linuxkit-x86_64-with-debian-11.5
[2023-02-17T08:22:58.584+0000] {connection.py:975} INFO - This connection is in OCSP Fail Open Mode. TLS Certificates would be checked for validity and revocation status. Any other Certificate Revocation related exceptions or OCSP Responder failures would be disregarded in favor of connectivity.
[2023-02-17T08:22:58.586+0000] {connection.py:992} INFO - Setting use_openssl_only mode to False
[2023-02-17T08:22:59.244+0000] {cursor.py:727} INFO - query: [select current_database(), current_schema();]
[2023-02-17T08:22:59.372+0000] {cursor.py:740} INFO - query execution done
[2023-02-17T08:22:59.375+0000] {cursor.py:879} INFO - Number of results in first chunk: 1
[2023-02-17T08:22:59.378+0000] {cursor.py:727} INFO - query: [ROLLBACK]
[2023-02-17T08:22:59.546+0000] {cursor.py:740} INFO - query execution done
[2023-02-17T08:22:59.551+0000] {cursor.py:879} INFO - Number of results in first chunk: 1
[2023-02-17T08:22:59.566+0000] {connection.py:285} INFO - Snowflake Connector for Python Version: 3.0.0, Python Version: 3.7.15, Platform: Linux-5.15.49-linuxkit-x86_64-with-debian-11.5
[2023-02-17T08:22:59.570+0000] {connection.py:975} INFO - This connection is in OCSP Fail Open Mode. TLS Certificates would be checked for validity and revocation status. Any other Certificate Revocation related exceptions or OCSP Responder failures would be disregarded in favor of connectivity.
[2023-02-17T08:23:00.135+0000] {cursor.py:727} INFO - query: [ROLLBACK]
[2023-02-17T08:23:00.273+0000] {cursor.py:740} INFO - query execution done
[2023-02-17T08:23:00.277+0000] {cursor.py:879} INFO - Number of results in first chunk: 1
[2023-02-17T08:23:00.281+0000] {cursor.py:727} INFO - query: [DESC TABLE /* sqlalchemy:_has_object */ manager_age]
[2023-02-17T08:23:00.422+0000] {cursor.py:740} INFO - query execution done
[2023-02-17T08:23:00.424+0000] {cursor.py:879} INFO - Number of results in first chunk: 4
[2023-02-17T08:23:00.426+0000] {cursor.py:727} INFO - query: [ROLLBACK]
[2023-02-17T08:23:00.561+0000] {cursor.py:740} INFO - query execution done
[2023-02-17T08:23:00.563+0000] {cursor.py:879} INFO - Number of results in first chunk: 1
[2023-02-17T08:23:00.565+0000] {taskinstance.py:1772} ERROR - Task failed with exception
Traceback (most recent call last):
  File "/home/airflow/.local/lib/python3.7/site-packages/airflow/operators/python.py", line 175, in execute
    return_value = self.execute_callable()
  File "/home/airflow/.local/lib/python3.7/site-packages/airflow/operators/python.py", line 192, in execute_callable
    return self.python_callable(*self.op_args, **self.op_kwargs)
  File "/opt/airflow/dags/dag_scrape_managers.py", line 78, in extract_data_send_to_snowflake
    df_managers.to_sql('manager_age', con=engine, index=False)
  File "/home/airflow/.local/lib/python3.7/site-packages/pandas/core/generic.py", line 2882, in to_sql
    method=method,
  File "/home/airflow/.local/lib/python3.7/site-packages/pandas/io/sql.py", line 728, in to_sql
    **engine_kwargs,
  File "/home/airflow/.local/lib/python3.7/site-packages/pandas/io/sql.py", line 1758, in to_sql
    dtype=dtype,
  File "/home/airflow/.local/lib/python3.7/site-packages/pandas/io/sql.py", line 1650, in prep_table
    table.create()
  File "/home/airflow/.local/lib/python3.7/site-packages/pandas/io/sql.py", line 858, in create
    raise ValueError(f"Table '{self.name}' already exists.")
ValueError: Table 'manager_age' already exists.
[2023-02-17T08:23:00.587+0000] {taskinstance.py:1327} INFO - Marking task as UP_FOR_RETRY. dag_id=dag_scrape_managers, task_id=EXTRACTING_DATA, execution_date=20230217T082252, start_date=20230217T082257, end_date=20230217T082300
[2023-02-17T08:23:00.616+0000] {warnings.py:110} WARNING - /home/***/.local/lib/python3.7/site-packages/***/utils/email.py:120: RemovedInAirflow3Warning: Fetching SMTP credentials from configuration variables will be deprecated in a future release. Please set credentials using a connection instead.
  send_mime_email(e_from=mail_from, e_to=recipients, mime_msg=msg, conn_id=conn_id, dryrun=dryrun)

[2023-02-17T08:23:00.618+0000] {configuration.py:635} WARNING - section/key [smtp/smtp_user] not found in config
[2023-02-17T08:23:00.619+0000] {email.py:229} INFO - Email alerting: attempt 1
[2023-02-17T08:23:00.632+0000] {configuration.py:635} WARNING - section/key [smtp/smtp_user] not found in config
[2023-02-17T08:23:00.634+0000] {email.py:229} INFO - Email alerting: attempt 1
[2023-02-17T08:23:00.636+0000] {taskinstance.py:1835} ERROR - Failed to send email to: test@test.com
Traceback (most recent call last):
  File "/home/airflow/.local/lib/python3.7/site-packages/airflow/models/taskinstance.py", line 1378, in _run_raw_task
    self._execute_task_with_callbacks(context, test_mode)
  File "/home/airflow/.local/lib/python3.7/site-packages/airflow/models/taskinstance.py", line 1524, in _execute_task_with_callbacks
    result = self._execute_task(context, task_orig)
  File "/home/airflow/.local/lib/python3.7/site-packages/airflow/models/taskinstance.py", line 1585, in _execute_task
    result = execute_callable(context=context)
  File "/home/airflow/.local/lib/python3.7/site-packages/airflow/operators/python.py", line 175, in execute
    return_value = self.execute_callable()
  File "/home/airflow/.local/lib/python3.7/site-packages/airflow/operators/python.py", line 192, in execute_callable
    return self.python_callable(*self.op_args, **self.op_kwargs)
  File "/opt/airflow/dags/dag_scrape_managers.py", line 78, in extract_data_send_to_snowflake
    df_managers.to_sql('manager_age', con=engine, index=False)
  File "/home/airflow/.local/lib/python3.7/site-packages/pandas/core/generic.py", line 2882, in to_sql
    method=method,
  File "/home/airflow/.local/lib/python3.7/site-packages/pandas/io/sql.py", line 728, in to_sql
    **engine_kwargs,
  File "/home/airflow/.local/lib/python3.7/site-packages/pandas/io/sql.py", line 1758, in to_sql
    dtype=dtype,
  File "/home/airflow/.local/lib/python3.7/site-packages/pandas/io/sql.py", line 1650, in prep_table
    table.create()
  File "/home/airflow/.local/lib/python3.7/site-packages/pandas/io/sql.py", line 858, in create
    raise ValueError(f"Table '{self.name}' already exists.")
ValueError: Table 'manager_age' already exists.

During handling of the above exception, another exception occurred:

Traceback (most recent call last):
  File "/home/airflow/.local/lib/python3.7/site-packages/airflow/models/taskinstance.py", line 2235, in email_alert
    send_email(task.email, subject, html_content)
  File "/home/airflow/.local/lib/python3.7/site-packages/airflow/utils/email.py", line 72, in send_email
    **kwargs,
  File "/home/airflow/.local/lib/python3.7/site-packages/airflow/utils/email.py", line 120, in send_email_smtp
    send_mime_email(e_from=mail_from, e_to=recipients, mime_msg=msg, conn_id=conn_id, dryrun=dryrun)
  File "/home/airflow/.local/lib/python3.7/site-packages/airflow/utils/email.py", line 231, in send_mime_email
    smtp_conn = _get_smtp_connection(smtp_host, smtp_port, smtp_timeout, smtp_ssl)
  File "/home/airflow/.local/lib/python3.7/site-packages/airflow/utils/email.py", line 265, in _get_smtp_connection
    else smtplib.SMTP(host=host, port=port, timeout=timeout)
  File "/usr/local/lib/python3.7/smtplib.py", line 251, in __init__
    (code, msg) = self.connect(host, port)
  File "/usr/local/lib/python3.7/smtplib.py", line 336, in connect
    self.sock = self._get_socket(host, port, self.timeout)
  File "/usr/local/lib/python3.7/smtplib.py", line 307, in _get_socket
    self.source_address)
  File "/usr/local/lib/python3.7/socket.py", line 728, in create_connection
    raise err
  File "/usr/local/lib/python3.7/socket.py", line 716, in create_connection
    sock.connect(sa)
OSError: [Errno 99] Cannot assign requested address

During handling of the above exception, another exception occurred:

Traceback (most recent call last):
  File "/home/airflow/.local/lib/python3.7/site-packages/airflow/models/taskinstance.py", line 1833, in handle_failure
    self.email_alert(error, task)
  File "/home/airflow/.local/lib/python3.7/site-packages/airflow/models/taskinstance.py", line 2237, in email_alert
    send_email(task.email, subject, html_content_err)
  File "/home/airflow/.local/lib/python3.7/site-packages/airflow/utils/email.py", line 72, in send_email
    **kwargs,
  File "/home/airflow/.local/lib/python3.7/site-packages/airflow/utils/email.py", line 120, in send_email_smtp
    send_mime_email(e_from=mail_from, e_to=recipients, mime_msg=msg, conn_id=conn_id, dryrun=dryrun)
  File "/home/airflow/.local/lib/python3.7/site-packages/airflow/utils/email.py", line 231, in send_mime_email
    smtp_conn = _get_smtp_connection(smtp_host, smtp_port, smtp_timeout, smtp_ssl)
  File "/home/airflow/.local/lib/python3.7/site-packages/airflow/utils/email.py", line 265, in _get_smtp_connection
    else smtplib.SMTP(host=host, port=port, timeout=timeout)
  File "/usr/local/lib/python3.7/smtplib.py", line 251, in __init__
    (code, msg) = self.connect(host, port)
  File "/usr/local/lib/python3.7/smtplib.py", line 336, in connect
    self.sock = self._get_socket(host, port, self.timeout)
  File "/usr/local/lib/python3.7/smtplib.py", line 307, in _get_socket
    self.source_address)
  File "/usr/local/lib/python3.7/socket.py", line 728, in create_connection
    raise err
  File "/usr/local/lib/python3.7/socket.py", line 716, in create_connection
    sock.connect(sa)
OSError: [Errno 99] Cannot assign requested address
[2023-02-17T08:23:00.669+0000] {standard_task_runner.py:105} ERROR - Failed to execute job 137 for task EXTRACTING_DATA (Table 'manager_age' already exists.; 294)
[2023-02-17T08:23:00.726+0000] {local_task_job.py:159} INFO - Task exited with return code 1
[2023-02-17T08:23:00.753+0000] {taskinstance.py:2582} INFO - 0 downstream tasks scheduled from follow-on schedule check
