[2023-02-16T11:29:43.028+0000] {taskinstance.py:1087} INFO - Dependencies all met for <TaskInstance: abcde.CONNECTION_SUCCESS manual__2023-02-16T11:27:12.495412+00:00 [queued]>
[2023-02-16T11:29:43.045+0000] {taskinstance.py:1087} INFO - Dependencies all met for <TaskInstance: abcde.CONNECTION_SUCCESS manual__2023-02-16T11:27:12.495412+00:00 [queued]>
[2023-02-16T11:29:43.047+0000] {taskinstance.py:1283} INFO - 
--------------------------------------------------------------------------------
[2023-02-16T11:29:43.048+0000] {taskinstance.py:1284} INFO - Starting attempt 1 of 2
[2023-02-16T11:29:43.050+0000] {taskinstance.py:1285} INFO - 
--------------------------------------------------------------------------------
[2023-02-16T11:29:43.075+0000] {taskinstance.py:1304} INFO - Executing <Task(PythonOperator): CONNECTION_SUCCESS> on 2023-02-16 11:27:12.495412+00:00
[2023-02-16T11:29:43.085+0000] {standard_task_runner.py:55} INFO - Started process 75 to run task
[2023-02-16T11:29:43.091+0000] {standard_task_runner.py:82} INFO - Running: ['***', 'tasks', 'run', 'abcde', 'CONNECTION_SUCCESS', 'manual__2023-02-16T11:27:12.495412+00:00', '--job-id', '116', '--raw', '--subdir', 'DAGS_FOLDER/dag_scrape_specific.py', '--cfg-path', '/tmp/tmpnj7urewe']
[2023-02-16T11:29:43.096+0000] {standard_task_runner.py:83} INFO - Job 116: Subtask CONNECTION_SUCCESS
[2023-02-16T11:29:43.448+0000] {task_command.py:389} INFO - Running <TaskInstance: abcde.CONNECTION_SUCCESS manual__2023-02-16T11:27:12.495412+00:00 [running]> on host 55b685598511
[2023-02-16T11:29:43.553+0000] {taskinstance.py:1513} INFO - Exporting the following env vars:
AIRFLOW_CTX_DAG_EMAIL=test@test.com
AIRFLOW_CTX_DAG_OWNER=test
AIRFLOW_CTX_DAG_ID=abcde
AIRFLOW_CTX_TASK_ID=CONNECTION_SUCCESS
AIRFLOW_CTX_EXECUTION_DATE=2023-02-16T11:27:12.495412+00:00
AIRFLOW_CTX_TRY_NUMBER=1
AIRFLOW_CTX_DAG_RUN_ID=manual__2023-02-16T11:27:12.495412+00:00
[2023-02-16T11:29:43.557+0000] {taskinstance.py:1772} ERROR - Task failed with exception
Traceback (most recent call last):
  File "/home/airflow/.local/lib/python3.7/site-packages/airflow/operators/python.py", line 175, in execute
    return_value = self.execute_callable()
  File "/home/airflow/.local/lib/python3.7/site-packages/airflow/operators/python.py", line 192, in execute_callable
    return self.python_callable(*self.op_args, **self.op_kwargs)
  File "/opt/airflow/dags/dag_scrape_specific.py", line 42, in validation_connection
    print('This is my Database : ' +str(conn.database))
AttributeError: 'Engine' object has no attribute 'database'
[2023-02-16T11:29:43.573+0000] {taskinstance.py:1327} INFO - Marking task as UP_FOR_RETRY. dag_id=abcde, task_id=CONNECTION_SUCCESS, execution_date=20230216T112712, start_date=20230216T112943, end_date=20230216T112943
[2023-02-16T11:29:43.604+0000] {warnings.py:110} WARNING - /home/***/.local/lib/python3.7/site-packages/***/utils/email.py:120: RemovedInAirflow3Warning: Fetching SMTP credentials from configuration variables will be deprecated in a future release. Please set credentials using a connection instead.
  send_mime_email(e_from=mail_from, e_to=recipients, mime_msg=msg, conn_id=conn_id, dryrun=dryrun)

[2023-02-16T11:29:43.606+0000] {configuration.py:635} WARNING - section/key [smtp/smtp_user] not found in config
[2023-02-16T11:29:43.608+0000] {email.py:229} INFO - Email alerting: attempt 1
[2023-02-16T11:29:43.623+0000] {configuration.py:635} WARNING - section/key [smtp/smtp_user] not found in config
[2023-02-16T11:29:43.625+0000] {email.py:229} INFO - Email alerting: attempt 1
[2023-02-16T11:29:43.627+0000] {taskinstance.py:1835} ERROR - Failed to send email to: test@test.com
Traceback (most recent call last):
  File "/home/airflow/.local/lib/python3.7/site-packages/airflow/models/taskinstance.py", line 1378, in _run_raw_task
    self._execute_task_with_callbacks(context, test_mode)
  File "/home/airflow/.local/lib/python3.7/site-packages/airflow/models/taskinstance.py", line 1524, in _execute_task_with_callbacks
    result = self._execute_task(context, task_orig)
  File "/home/airflow/.local/lib/python3.7/site-packages/airflow/models/taskinstance.py", line 1585, in _execute_task
    result = execute_callable(context=context)
  File "/home/airflow/.local/lib/python3.7/site-packages/airflow/operators/python.py", line 175, in execute
    return_value = self.execute_callable()
  File "/home/airflow/.local/lib/python3.7/site-packages/airflow/operators/python.py", line 192, in execute_callable
    return self.python_callable(*self.op_args, **self.op_kwargs)
  File "/opt/airflow/dags/dag_scrape_specific.py", line 42, in validation_connection
    print('This is my Database : ' +str(conn.database))
AttributeError: 'Engine' object has no attribute 'database'

During handling of the above exception, another exception occurred:

Traceback (most recent call last):
  File "/home/airflow/.local/lib/python3.7/site-packages/airflow/models/taskinstance.py", line 2235, in email_alert
    send_email(task.email, subject, html_content)
  File "/home/airflow/.local/lib/python3.7/site-packages/airflow/utils/email.py", line 72, in send_email
    **kwargs,
  File "/home/airflow/.local/lib/python3.7/site-packages/airflow/utils/email.py", line 120, in send_email_smtp
    send_mime_email(e_from=mail_from, e_to=recipients, mime_msg=msg, conn_id=conn_id, dryrun=dryrun)
  File "/home/airflow/.local/lib/python3.7/site-packages/airflow/utils/email.py", line 231, in send_mime_email
    smtp_conn = _get_smtp_connection(smtp_host, smtp_port, smtp_timeout, smtp_ssl)
  File "/home/airflow/.local/lib/python3.7/site-packages/airflow/utils/email.py", line 265, in _get_smtp_connection
    else smtplib.SMTP(host=host, port=port, timeout=timeout)
  File "/usr/local/lib/python3.7/smtplib.py", line 251, in __init__
    (code, msg) = self.connect(host, port)
  File "/usr/local/lib/python3.7/smtplib.py", line 336, in connect
    self.sock = self._get_socket(host, port, self.timeout)
  File "/usr/local/lib/python3.7/smtplib.py", line 307, in _get_socket
    self.source_address)
  File "/usr/local/lib/python3.7/socket.py", line 728, in create_connection
    raise err
  File "/usr/local/lib/python3.7/socket.py", line 716, in create_connection
    sock.connect(sa)
OSError: [Errno 99] Cannot assign requested address

During handling of the above exception, another exception occurred:

Traceback (most recent call last):
  File "/home/airflow/.local/lib/python3.7/site-packages/airflow/models/taskinstance.py", line 1833, in handle_failure
    self.email_alert(error, task)
  File "/home/airflow/.local/lib/python3.7/site-packages/airflow/models/taskinstance.py", line 2237, in email_alert
    send_email(task.email, subject, html_content_err)
  File "/home/airflow/.local/lib/python3.7/site-packages/airflow/utils/email.py", line 72, in send_email
    **kwargs,
  File "/home/airflow/.local/lib/python3.7/site-packages/airflow/utils/email.py", line 120, in send_email_smtp
    send_mime_email(e_from=mail_from, e_to=recipients, mime_msg=msg, conn_id=conn_id, dryrun=dryrun)
  File "/home/airflow/.local/lib/python3.7/site-packages/airflow/utils/email.py", line 231, in send_mime_email
    smtp_conn = _get_smtp_connection(smtp_host, smtp_port, smtp_timeout, smtp_ssl)
  File "/home/airflow/.local/lib/python3.7/site-packages/airflow/utils/email.py", line 265, in _get_smtp_connection
    else smtplib.SMTP(host=host, port=port, timeout=timeout)
  File "/usr/local/lib/python3.7/smtplib.py", line 251, in __init__
    (code, msg) = self.connect(host, port)
  File "/usr/local/lib/python3.7/smtplib.py", line 336, in connect
    self.sock = self._get_socket(host, port, self.timeout)
  File "/usr/local/lib/python3.7/smtplib.py", line 307, in _get_socket
    self.source_address)
  File "/usr/local/lib/python3.7/socket.py", line 728, in create_connection
    raise err
  File "/usr/local/lib/python3.7/socket.py", line 716, in create_connection
    sock.connect(sa)
OSError: [Errno 99] Cannot assign requested address
[2023-02-16T11:29:43.659+0000] {standard_task_runner.py:105} ERROR - Failed to execute job 116 for task CONNECTION_SUCCESS ('Engine' object has no attribute 'database'; 75)
[2023-02-16T11:29:43.706+0000] {local_task_job.py:159} INFO - Task exited with return code 1
