[2023-02-16T10:57:14.785+0000] {taskinstance.py:1087} INFO - Dependencies all met for <TaskInstance: abcd.EXTRACTING_DATA manual__2023-02-16T10:57:08.997860+00:00 [queued]>
[2023-02-16T10:57:14.804+0000] {taskinstance.py:1087} INFO - Dependencies all met for <TaskInstance: abcd.EXTRACTING_DATA manual__2023-02-16T10:57:08.997860+00:00 [queued]>
[2023-02-16T10:57:14.805+0000] {taskinstance.py:1283} INFO - 
--------------------------------------------------------------------------------
[2023-02-16T10:57:14.807+0000] {taskinstance.py:1284} INFO - Starting attempt 1 of 2
[2023-02-16T10:57:14.808+0000] {taskinstance.py:1285} INFO - 
--------------------------------------------------------------------------------
[2023-02-16T10:57:14.841+0000] {taskinstance.py:1304} INFO - Executing <Task(PythonOperator): EXTRACTING_DATA> on 2023-02-16 10:57:08.997860+00:00
[2023-02-16T10:57:14.850+0000] {standard_task_runner.py:55} INFO - Started process 335 to run task
[2023-02-16T10:57:14.856+0000] {standard_task_runner.py:82} INFO - Running: ['***', 'tasks', 'run', 'abcd', 'EXTRACTING_DATA', 'manual__2023-02-16T10:57:08.997860+00:00', '--job-id', '112', '--raw', '--subdir', 'DAGS_FOLDER/dag_scrape_specific.py', '--cfg-path', '/tmp/tmpr6hc2yj2']
[2023-02-16T10:57:14.858+0000] {standard_task_runner.py:83} INFO - Job 112: Subtask EXTRACTING_DATA
[2023-02-16T10:57:14.977+0000] {task_command.py:389} INFO - Running <TaskInstance: abcd.EXTRACTING_DATA manual__2023-02-16T10:57:08.997860+00:00 [running]> on host 55b685598511
[2023-02-16T10:57:15.105+0000] {taskinstance.py:1513} INFO - Exporting the following env vars:
AIRFLOW_CTX_DAG_EMAIL=test@test.com
AIRFLOW_CTX_DAG_OWNER=test
AIRFLOW_CTX_DAG_ID=abcd
AIRFLOW_CTX_TASK_ID=EXTRACTING_DATA
AIRFLOW_CTX_EXECUTION_DATE=2023-02-16T10:57:08.997860+00:00
AIRFLOW_CTX_TRY_NUMBER=1
AIRFLOW_CTX_DAG_RUN_ID=manual__2023-02-16T10:57:08.997860+00:00
[2023-02-16T10:57:15.910+0000] {cursor.py:727} INFO - query: [ROLLBACK]
[2023-02-16T10:57:16.102+0000] {cursor.py:740} INFO - query execution done
[2023-02-16T10:57:16.104+0000] {cursor.py:879} INFO - Number of results in first chunk: 1
[2023-02-16T10:57:16.106+0000] {taskinstance.py:1772} ERROR - Task failed with exception
Traceback (most recent call last):
  File "/home/airflow/.local/lib/python3.7/site-packages/pandas/io/sql.py", line 2056, in execute
    cur.execute(*args, **kwargs)
  File "/home/airflow/.local/lib/python3.7/site-packages/snowflake/connector/cursor.py", line 695, in execute
    query = self._preprocess_pyformat_query(command, params)
  File "/home/airflow/.local/lib/python3.7/site-packages/snowflake/connector/cursor.py", line 594, in _preprocess_pyformat_query
    query = command % processed_params
TypeError: not all arguments converted during string formatting

The above exception was the direct cause of the following exception:

Traceback (most recent call last):
  File "/home/airflow/.local/lib/python3.7/site-packages/airflow/operators/python.py", line 175, in execute
    return_value = self.execute_callable()
  File "/home/airflow/.local/lib/python3.7/site-packages/airflow/operators/python.py", line 192, in execute_callable
    return self.python_callable(*self.op_args, **self.op_kwargs)
  File "/opt/airflow/dags/dag_scrape_specific.py", line 53, in extract_data_send_to_snowflake
    df_test.to_sql('match_results', con=engine, index=False)
  File "/home/airflow/.local/lib/python3.7/site-packages/pandas/core/generic.py", line 2882, in to_sql
    method=method,
  File "/home/airflow/.local/lib/python3.7/site-packages/pandas/io/sql.py", line 728, in to_sql
    **engine_kwargs,
  File "/home/airflow/.local/lib/python3.7/site-packages/pandas/io/sql.py", line 2225, in to_sql
    table.create()
  File "/home/airflow/.local/lib/python3.7/site-packages/pandas/io/sql.py", line 856, in create
    if self.exists():
  File "/home/airflow/.local/lib/python3.7/site-packages/pandas/io/sql.py", line 840, in exists
    return self.pd_sql.has_table(self.name, self.schema)
  File "/home/airflow/.local/lib/python3.7/site-packages/pandas/io/sql.py", line 2236, in has_table
    return len(self.execute(query, [name]).fetchall()) > 0
  File "/home/airflow/.local/lib/python3.7/site-packages/pandas/io/sql.py", line 2068, in execute
    raise ex from exc
pandas.io.sql.DatabaseError: Execution failed on sql 'SELECT name FROM sqlite_master WHERE type='table' AND name=?;': not all arguments converted during string formatting
[2023-02-16T10:57:16.128+0000] {taskinstance.py:1327} INFO - Marking task as UP_FOR_RETRY. dag_id=abcd, task_id=EXTRACTING_DATA, execution_date=20230216T105708, start_date=20230216T105714, end_date=20230216T105716
[2023-02-16T10:57:16.148+0000] {warnings.py:110} WARNING - /home/***/.local/lib/python3.7/site-packages/***/utils/email.py:120: RemovedInAirflow3Warning: Fetching SMTP credentials from configuration variables will be deprecated in a future release. Please set credentials using a connection instead.
  send_mime_email(e_from=mail_from, e_to=recipients, mime_msg=msg, conn_id=conn_id, dryrun=dryrun)

[2023-02-16T10:57:16.149+0000] {configuration.py:635} WARNING - section/key [smtp/smtp_user] not found in config
[2023-02-16T10:57:16.151+0000] {email.py:229} INFO - Email alerting: attempt 1
[2023-02-16T10:57:16.168+0000] {configuration.py:635} WARNING - section/key [smtp/smtp_user] not found in config
[2023-02-16T10:57:16.170+0000] {email.py:229} INFO - Email alerting: attempt 1
[2023-02-16T10:57:16.171+0000] {taskinstance.py:1835} ERROR - Failed to send email to: test@test.com
Traceback (most recent call last):
  File "/home/airflow/.local/lib/python3.7/site-packages/pandas/io/sql.py", line 2056, in execute
    cur.execute(*args, **kwargs)
  File "/home/airflow/.local/lib/python3.7/site-packages/snowflake/connector/cursor.py", line 695, in execute
    query = self._preprocess_pyformat_query(command, params)
  File "/home/airflow/.local/lib/python3.7/site-packages/snowflake/connector/cursor.py", line 594, in _preprocess_pyformat_query
    query = command % processed_params
TypeError: not all arguments converted during string formatting

The above exception was the direct cause of the following exception:

Traceback (most recent call last):
  File "/home/airflow/.local/lib/python3.7/site-packages/airflow/models/taskinstance.py", line 1378, in _run_raw_task
    self._execute_task_with_callbacks(context, test_mode)
  File "/home/airflow/.local/lib/python3.7/site-packages/airflow/models/taskinstance.py", line 1524, in _execute_task_with_callbacks
    result = self._execute_task(context, task_orig)
  File "/home/airflow/.local/lib/python3.7/site-packages/airflow/models/taskinstance.py", line 1585, in _execute_task
    result = execute_callable(context=context)
  File "/home/airflow/.local/lib/python3.7/site-packages/airflow/operators/python.py", line 175, in execute
    return_value = self.execute_callable()
  File "/home/airflow/.local/lib/python3.7/site-packages/airflow/operators/python.py", line 192, in execute_callable
    return self.python_callable(*self.op_args, **self.op_kwargs)
  File "/opt/airflow/dags/dag_scrape_specific.py", line 53, in extract_data_send_to_snowflake
    df_test.to_sql('match_results', con=engine, index=False)
  File "/home/airflow/.local/lib/python3.7/site-packages/pandas/core/generic.py", line 2882, in to_sql
    method=method,
  File "/home/airflow/.local/lib/python3.7/site-packages/pandas/io/sql.py", line 728, in to_sql
    **engine_kwargs,
  File "/home/airflow/.local/lib/python3.7/site-packages/pandas/io/sql.py", line 2225, in to_sql
    table.create()
  File "/home/airflow/.local/lib/python3.7/site-packages/pandas/io/sql.py", line 856, in create
    if self.exists():
  File "/home/airflow/.local/lib/python3.7/site-packages/pandas/io/sql.py", line 840, in exists
    return self.pd_sql.has_table(self.name, self.schema)
  File "/home/airflow/.local/lib/python3.7/site-packages/pandas/io/sql.py", line 2236, in has_table
    return len(self.execute(query, [name]).fetchall()) > 0
  File "/home/airflow/.local/lib/python3.7/site-packages/pandas/io/sql.py", line 2068, in execute
    raise ex from exc
pandas.io.sql.DatabaseError: Execution failed on sql 'SELECT name FROM sqlite_master WHERE type='table' AND name=?;': not all arguments converted during string formatting

During handling of the above exception, another exception occurred:

Traceback (most recent call last):
  File "/home/airflow/.local/lib/python3.7/site-packages/airflow/models/taskinstance.py", line 2235, in email_alert
    send_email(task.email, subject, html_content)
  File "/home/airflow/.local/lib/python3.7/site-packages/airflow/utils/email.py", line 72, in send_email
    **kwargs,
  File "/home/airflow/.local/lib/python3.7/site-packages/airflow/utils/email.py", line 120, in send_email_smtp
    send_mime_email(e_from=mail_from, e_to=recipients, mime_msg=msg, conn_id=conn_id, dryrun=dryrun)
  File "/home/airflow/.local/lib/python3.7/site-packages/airflow/utils/email.py", line 231, in send_mime_email
    smtp_conn = _get_smtp_connection(smtp_host, smtp_port, smtp_timeout, smtp_ssl)
  File "/home/airflow/.local/lib/python3.7/site-packages/airflow/utils/email.py", line 265, in _get_smtp_connection
    else smtplib.SMTP(host=host, port=port, timeout=timeout)
  File "/usr/local/lib/python3.7/smtplib.py", line 251, in __init__
    (code, msg) = self.connect(host, port)
  File "/usr/local/lib/python3.7/smtplib.py", line 336, in connect
    self.sock = self._get_socket(host, port, self.timeout)
  File "/usr/local/lib/python3.7/smtplib.py", line 307, in _get_socket
    self.source_address)
  File "/usr/local/lib/python3.7/socket.py", line 728, in create_connection
    raise err
  File "/usr/local/lib/python3.7/socket.py", line 716, in create_connection
    sock.connect(sa)
OSError: [Errno 99] Cannot assign requested address

During handling of the above exception, another exception occurred:

Traceback (most recent call last):
  File "/home/airflow/.local/lib/python3.7/site-packages/airflow/models/taskinstance.py", line 1833, in handle_failure
    self.email_alert(error, task)
  File "/home/airflow/.local/lib/python3.7/site-packages/airflow/models/taskinstance.py", line 2237, in email_alert
    send_email(task.email, subject, html_content_err)
  File "/home/airflow/.local/lib/python3.7/site-packages/airflow/utils/email.py", line 72, in send_email
    **kwargs,
  File "/home/airflow/.local/lib/python3.7/site-packages/airflow/utils/email.py", line 120, in send_email_smtp
    send_mime_email(e_from=mail_from, e_to=recipients, mime_msg=msg, conn_id=conn_id, dryrun=dryrun)
  File "/home/airflow/.local/lib/python3.7/site-packages/airflow/utils/email.py", line 231, in send_mime_email
    smtp_conn = _get_smtp_connection(smtp_host, smtp_port, smtp_timeout, smtp_ssl)
  File "/home/airflow/.local/lib/python3.7/site-packages/airflow/utils/email.py", line 265, in _get_smtp_connection
    else smtplib.SMTP(host=host, port=port, timeout=timeout)
  File "/usr/local/lib/python3.7/smtplib.py", line 251, in __init__
    (code, msg) = self.connect(host, port)
  File "/usr/local/lib/python3.7/smtplib.py", line 336, in connect
    self.sock = self._get_socket(host, port, self.timeout)
  File "/usr/local/lib/python3.7/smtplib.py", line 307, in _get_socket
    self.source_address)
  File "/usr/local/lib/python3.7/socket.py", line 728, in create_connection
    raise err
  File "/usr/local/lib/python3.7/socket.py", line 716, in create_connection
    sock.connect(sa)
OSError: [Errno 99] Cannot assign requested address
[2023-02-16T10:57:16.193+0000] {standard_task_runner.py:105} ERROR - Failed to execute job 112 for task EXTRACTING_DATA (Execution failed on sql 'SELECT name FROM sqlite_master WHERE type='table' AND name=?;': not all arguments converted during string formatting; 335)
[2023-02-16T10:57:16.234+0000] {local_task_job.py:159} INFO - Task exited with return code 1
[2023-02-16T10:57:16.267+0000] {taskinstance.py:2582} INFO - 0 downstream tasks scheduled from follow-on schedule check
